#VRML_SIM R2021b utf8
# license: Apache License 2.0
# license url: http://www.apache.org/licenses/LICENSE-2.0
# This is a proto file for Webots for the robleo
# Extracted from: /home/mcfurry/ros/foxy/install/robleo_description/share/robleo_description/urdf/robleo.urdf

PROTO robleo [
  field  SFVec3f     translation     0 0 0
  field  SFRotation  rotation        0 1 0 0
  field  SFString    name            "robleo"  # Is `Robot.name`.
  field  SFString    controller      "void"    # Is `Robot.controller`.
  field  MFString    controllerArgs  []        # Is `Robot.controllerArgs`.
  field  SFString    customData      ""        # Is `Robot.customData`.
  field  SFBool      supervisor      FALSE     # Is `Robot.supervisor`.
  field  SFBool      synchronization TRUE      # Is `Robot.synchronization`.
  field  SFBool      selfCollision   FALSE     # Is `Robot.selfCollision`.
]
{
  Robot {
    translation IS translation
    rotation IS rotation
    controller IS controller
    controllerArgs IS controllerArgs
    customData IS customData
    supervisor IS supervisor
    synchronization IS synchronization
    selfCollision IS selfCollision
    children [
      Transform {
        translation 0.000000 0.000000 0.000000
        rotation 1.000000 0.000000 0.000000 1.570796
        children [
          Shape {
            appearance DEF Cyan PBRAppearance {
              baseColor 0.000000 1.000000 1.000000
              transparency 0.000000
              roughness 1.000000
              metalness 0
              emissiveColor 0.000000 0.000000 0.000000
            }
            geometry Cylinder {
              radius 0.22
              height 0.2
            }
          }
        ]
      }
      HingeJoint {
        jointParameters HingeJointParameters {
          axis 0.000000 1.000000 0.000796
          anchor 0.000000 0.250000 0.000000
          dampingConstant 0.0
          staticFriction 0.0
        }
        device [
          RotationalMotor {
            name "wheel_left_joint"
            maxTorque 10000
          }
          PositionSensor {
            name "wheel_left_joint_sensor"
          }
        ]
        endPoint Solid {
          translation 0.000000 0.250000 0.000000
          rotation -1.000000 0.000000 0.000000 1.570000
          children [
            Transform {
              translation 0.000000 0.000000 0.000000
              rotation 1.000000 0.000000 0.000000 1.570796
              children [
                Shape {
                  appearance DEF Green PBRAppearance {
                    baseColor 0.000000 1.000000 0.200000
                    transparency 0.000000
                    roughness 1.000000
                    metalness 0
                    emissiveColor 0.000000 0.000000 0.000000
                  }
                  geometry Cylinder {
                    radius 0.11
                    height 0.05
                  }
                }
              ]
            }
          ]
          name "wheel_left_link"
          boundingObject Transform {
            translation 0.000000 0.000000 0.000000
            rotation 1.000000 0.000000 0.000000 1.570796
            children [
              Cylinder {
                radius 0.11
                height 0.05
              }
            ]
          }
          physics Physics {
            density -1
            mass 0.028499
            centerOfMass [ 0.000000 0.000000 0.000000 ]
            inertiaMatrix [
              1.117558e-05 1.119241e-05 2.071256e-05
              -4.236978e-11 -5.938172e-09 -1.440011e-11
            ]
          }
        }
      }
      HingeJoint {
        jointParameters HingeJointParameters {
          axis 0.000000 -1.000000 0.000796
          anchor 0.000000 -0.250000 0.000000
          dampingConstant 0.0
          staticFriction 0.0
        }
        device [
          RotationalMotor {
            name "wheel_right_joint"
            maxTorque 10000
          }
          PositionSensor {
            name "wheel_right_joint_sensor"
          }
        ]
        endPoint Solid {
          translation 0.000000 -0.250000 0.000000
          rotation 1.000000 0.000000 0.000000 1.570000
          children [
            Transform {
              translation 0.000000 0.000000 0.000000
              rotation 1.000000 0.000000 0.000000 1.570796
              children [
                Shape {
                  appearance USE Green
                  geometry Cylinder {
                    radius 0.11
                    height 0.05
                  }
                }
              ]
            }
          ]
          name "wheel_right_link"
          boundingObject Transform {
            translation 0.000000 0.000000 0.000000
            rotation 1.000000 0.000000 0.000000 1.570796
            children [
              Cylinder {
                radius 0.11
                height 0.05
              }
            ]
          }
          physics Physics {
            density -1
            mass 0.028499
            centerOfMass [ 0.000000 0.000000 0.000000 ]
            inertiaMatrix [
              1.117558e-05 1.119241e-05 2.071256e-05
              -4.236978e-11 -5.938172e-09 -1.440011e-11
            ]
          }
        }
      }
    ]
    name IS name 
    boundingObject Transform {
      translation 0.000000 0.000000 0.000000
      rotation 1.000000 0.000000 0.000000 1.570796
      children [
        Cylinder {
          radius 0.22
          height 0.2
        }
      ]
    }
    physics Physics {
      density -1
      mass 0.825735
      centerOfMass [ 0.000000 0.000000 0.100000 ]
      inertiaMatrix [
        2.212442e-03 2.119370e-03 2.006427e-03
        -1.229410e-05 3.493878e-05 -5.012090e-06
      ]
    }
  }
}
